#VRML_SIM R2019a utf8
WorldInfo {
}
Viewpoint {
  orientation -0.8290379002149348 -0.5447095056403138 -0.12644253426872057 0.5906362751909742
  position -0.5015079486187466 0.8356962667189889 0.8416884221430766
}
TexturedBackground {
}
TexturedBackgroundLight {
}
Floor {
}
Solid {
  translation 0 0.25 0
  children [
    Shape {
      appearance PBRAppearance {
        baseColor 0.20392156862745098 0.396078431372549 0.6431372549019608
        roughness 1
        metalness 0
      }
      geometry Cylinder {
        height 0.5
        radius 0.05
      }
    }
    HingeJoint {
      jointParameters HingeJointParameters {
        axis 0 1 0
        anchor 0 0.255 0
        minStop -0.7854
        maxStop 0.7854
        staticFriction 0.1
      }
      endPoint Solid {
        translation 1.3675992512423277e-16 0.2549696864734279 1.9324671673076604e-16
        rotation 5.5073597621792776e-14 -1 1.8153345337643043e-13 0.000307730471958297
        children [
          Shape {
            appearance DEF Red PBRAppearance {
              baseColor 0.8 0 0
              roughness 1
              metalness 0
            }
            geometry Box {
              size 0.8 0.01 0.1
            }
          }
        ]
        physics Physics {
        }
      }
    }
    HingeJoint {
      jointParameters HingeJointParameters {
        axis 0 1 0
      }
      endPoint Solid {
        translation -0.05499999999999999 -2.5253789220986947e-05 1.6767707750785113e-05
        rotation -0.9999999999999999 1.2445887245304366e-173 7.794672514360458e-174 6.270530553917715
        children [
          Shape {
            appearance USE Red
            geometry Box {
              size 0.01 0.03 0.1
            }
          }
        ]
        name "solid(1)"
        physics Physics {
        }
      }
    }
  ]
}
