#VRML_SIM R2019a utf8
WorldInfo {
}
Viewpoint {
  orientation -0.980097478553885 -0.19787264313959918 -0.01597966298974996 0.34631810329736074
  position -0.04163996432820044 0.7434501321857152 0.9308024194641987
}
TexturedBackground {
}
TexturedBackgroundLight {
}
Floor {
}
Solid {
  translation 0 0.25 0
  children [
    Shape {
      appearance PBRAppearance {
        baseColor 0.20392156862745098 0.396078431372549 0.6431372549019608
        roughness 1
        metalness 0
      }
      geometry Cylinder {
        height 0.5
        radius 0.05
      }
    }
    HingeJoint {
      jointParameters HingeJointParameters {
        axis 0 1 0
        anchor 0 0.255 0
        staticFriction 0.1
      }
      endPoint Solid {
        translation 0 0.255 0
        children [
          Shape {
            appearance PBRAppearance {
              baseColor 0.8 0 0
              roughness 1
              metalness 0
            }
            geometry Box {
              size 0.8 0.01 0.1
            }
          }
        ]
        physics Physics {
        }
      }
    }
  ]
}
